Workbook

Sheet Work Card Inquiry
A1: GAES WO# | B1: GAES Source Card# | C1: CUST. CARD | D1: PROJECT | E1: ORDER TYPE | F1: DESCRIPTION | G1: CORRECTIVE ACTION
A2: 20091-0001 | B2: - | C2: WY | D2: CN-RGA-1 | E2: ROUTINE | F2: WEEKLY CHECK REF TASK WY | G2: COMPLETED. TLB# TL2311637 ITEM "C".
A3: 20092-0001 | B3: - | C3: 12-004-00-01 | D3: CN-RGA-1 | E3: ROUTINE | F3: CHANGE ENGINE 1 INTEGRATED DRIVE GENERATOR OIL. REF TASK 12-004-00-01 | G3: COMPLETED.
A4: 20092-0002 | B4: - | C4: 12-004-00-02 | D4: CN-RGA-1 | E4: ROUTINE | F4: CHANGE ENGINE 2 INTEGRATED DRIVE GENERATOR OIL. REF TASK 12-004-00-02 | G4: COMPLETED.
A5: 20092-0003 | B5: - | C5: 12-004-00-03 | D5: CN-RGA-1 | E5: ROUTINE | F5: CHANGE ENGINE 3 INTEGRATED DRIVE GENERATOR OIL. REF TASK 12-004-00-03 | G5: COMPLETED.
A6: 20092-0004 | B6: - | C6: 12-004-00-04 | D6: CN-RGA-1 | E6: ROUTINE | F6: CHANGE ENGINE 4 INTEGRATED DRIVE GENERATOR OIL. REF TASK 12-004-00-04 | G6: COMPLETED.
A7: 20092-0005 | B7: - | C7: 12-078-00-04 | D7: CN-RGA-1 | E7: ROUTINE | F7: FUNCTIONALLY CHECK THE TIRE PRESSURE INDICATION SYSTEM, IF INSTALLED. REF TASK 12-078-00-04 | G7: COMPLETED.
A8: 20092-0006 | B8: - | C8: 12-080-00 | D8: CN-RGA-1 | E8: ROUTINE | F8: FUNCTIONAL CHECK OF THE PARKING BRAKE ACCUMULATOR CHARGE PRESSURE. REF TASK 12-080-00 | G8: COMPLETED.
A9: 20092-0007 | B9: - | C9: 12-082-00-01 | D9: CN-RGA-1 | E9: ROUTINE | F9: SERVICE THE BRAKE SURGE ACCUMULATOR PRECHARGE (RIGHT BODY LANDING GEAR WELL). REF TASK 12-082-00-01 | G9: COMPLETED.
A10: 20092-0008 | B10: - | C10: 12-082-00-02 | D10: CN-RGA-1 | E10: ROUTINE | F10: SERVICE THE BRAKE SURGE ACCUMULATOR PRECHARGE (LEFT WING REAR SPAR TO LANDING GEAR SUPPORT BEAM). REF TASK 12-082-00-02 | G10: COMPLETED.
A11: 20092-0009 | B11: - | C11: 12-082-00-03 | D11: CN-RGA-1 | E11: ROUTINE | F11: SERVICE THE BRAKE SURGE ACCUMULATOR PRECHARGE (RIGHT REAR SPAR TO LANDING GEAR SUPPORT BEAM). REF TASK 12-082-00-03 | G11: COMPLETED.
A12: 20092-0010 | B12: - | C12: 12-084-00-01 | D12: CN-RGA-1 | E12: ROUTINE | F12: LUBRICATE LEFT BODY LANDING GEAR TRUCK BEAM PIVOT BOLT. REF TASK 12-084-00-01 | G12: COMPLETED.
... A638: 20110-0010 | B638: - | C638: GAES PROCEDURE | D638: CN-RGA-1 | E638: NONROUTINE | F638: PERFORM REMOVAL/INSTALLATION OF ACCESS PANELS FOR ZONE 800 AS PER PANEL CLEARANCE SHEETS GAES-148-AMO-REV00-JUL2023 | G638: COMPLETED.
A639: 20110-0011 | B639: 20097-0022 | D639: CN-RGA-1 | E639: NONROUTINE | F639: ENG 4- *BLEED PRV ENG 4* STATUS MESSAGE. PERFORM CORRECTIVE ACTION | G639: COMPLETED.
A640: 20110-0012 | B640: 20099-0034 | D640: CN-RGA-1 | E640: NONROUTINE | F640: CARRY OUT REMOVAL AND INSTALLATION OF PAX SEATS FROM STA 1000 TO STA 1480 (19ABC HJK TO 39 ABC HJK) BOTH LH AND RH SIDE TO ACCESS THE FLOOR PANEL. | G640: COMPLETED.
A641: 20110-0013 | B641: 20092-0083 | D641: CN-RGA-1 | E641: NONROUTINE | F641: ENG 3- INLET COWL INNER ACOUSTIC PANEL BULGIE ON 6'0 CLOCK POSITION . PERFORM CORRECTIVE ACTION | G641: COMPLETED.
A642: 20110-0014 | B642: 20099-0054 | D642: CN-RGA-1 | E642: NONROUTINE | F642: PERFORM CLEANING OF THE FAN COWLS,T/RS AND CORE COWLS INNER SURFACE FOR ALL ENGINES. | G642: COMPLETED.
A643: 20110-0015 | B643: 20099-0032 | D643: CN-RGA-1 | E643: NONROUTINE | F643: IN LAVATORY FC2 THE WASTE COMPARTMENT FLAPPER IS WEAK. | G643: COMPLETED.
A644: 20110-0016 | B644: 20099-0032 | D644: CN-RGA-1 | E644: NONROUTINE | F644: IN LAVATORY BS2 THE WASTE COMPARTMENT DOOR SCREWS QTY 3 ARE MISSING. | G644: COMPLETED.
A645: 20110-0017 | B645: 20099-0032 | D645: CN-RGA-1 | E645: NONROUTINE | F645: IN LAVATORY FC2 THE WASTE CONTAINER IS DIRTY. | G645: COMPLETED.
A646: 20110-0018 | B646: 20092-0079 | D646: CN-RGA-1 | E646: NONROUTINE | F646: RH WING LE UPPER FIXED PANEL FOUND PUNCTURE BETWEEN OLES 1639.00 AND WBL 1241.00. PLS RECTIFY. | G646: COMPLETED.
A647: 20110-0019 | B647: 20092-0030 | D647: CN-RGA-1 | E647: NONROUTINE | F647: MAIN 3 AFT OVRD/JETTISON PUMP "LOW PRESSURE'' LIGHT IS NOT ILLUMINATING. PERFORM CORRECTIVE ACTION | G647: COMPLETED.
A648: 20110-0020 | B648: 20092-0049 | D648: CN-RGA-1 | E648: NONROUTINE | F648: MASTER DIM AND TEST MODULE OPC FAILED: INDICATOR LIGHTS DOESN'T GO OFF WHEN SWITCH PLACED FROM "TEST" TO "BRIGHT" POSITION. PERFORM CORRECTIVE ACTION | G648: COMPLETED.
A649: 20110-0021 | B649: 20092-0026 | D649: CN-RGA-1 | E649: NONROUTINE | F649: FOUND INTERMITTENT PRESENT LEG FAULT, MMSG 26040: ''ENGINE BOTTLE RIGHT-A LOW PRESSURE'' AND ''BTL LOW R ENG A'' STATUS MSG. PERFORM CORRECTIVE ACTION | G649: COMPLETED.
A650: 20110-0022 | B650: 20092-0084 | D650: CN-RGA-1 | E650: NONROUTINE | F650: PERFORM REPAIR OF THE ENG#4 RH T/R FILLER . | G650: COMPLETED.
... A722: 20110-0094 | B722: 20110-0002 | D722: CN-RGA-1 | E722: NONROUTINE | F722: ENG 4 -DURING ENGINE START FOUND *BLD 4 OVHT/PRV* ADVISORY MESSAGE APPEAR. PERFORM CORRECTIVE ACTION | G722: TO AVOID DELAY AIRCARFT DISPATCHED I.A.W MEL 36-11-08B AND MEL 78-31-01 REV.01 CAT "C" ENGINE NO. 4 THRUST REVERSER DEACTIVATED. REFER TO TLB# TL2311637 ITEM "B".
A723: 20114-0001 | B723: - | C723: CWR-001 | D723: CN-RGA-1 | E723: CWR | F723: PERFORM AICRAFT EXTERNAL WASH | G723: COMPLETED.
A724: 20116-0001 | B724: - | D724: AP-BNU-1 | E724: GENERIC | F724: TASK CARD CREATED TO LINK MATERIALS ORDERED FOR PHASE 1, BUT POSTPONNED TO PHASE 2 | G724: CANCELLED. ALL RQ TRASNFERRED TO NRC RQ
A725: 20116-0002 | B725: - | D725: AP-BNU-1 | E725: GENERIC | F725: TASK CARD CREATED TO ORDER PAINT MATERIALS AND TRACKING ONLY. REPAINT THE AIRCRAFT PER EOD-B747-51-21-0001 1/4 & 2/4 INSTRUCTIONS. PERFORM A POST PAINT CONTROL AND SURFACE BALANCING PER EOD-B747-51-21-0001 3/4 INSTRUCTIONS. REF TASK AMES/MP/10-007 RT717-BM-2401-1 | G725: CANCELLED. ALL REQUISITON TRANSFERRED TO 20148-0001
A726: 20117-0001 | B726: - | C726: 27-062-06 | D726: CN-RGA-1 | E726: ROUTINE | F726: PERFORM AN OPERATIONAL CHECK OF THE AUTO SPEED BRAKE ACTUATION SYSTEM AND THE CONTROL STAND CAM MECHANISM. REF TASK 27-062-06 | G726: REFER TO RC# 20097-0016
A727: 20117-0002 | B727: - | C727: 28-022-04 | D727: CN-RGA-1 | E727: ROUTINE | F727: OPERATIONALLY CHECK THE ENGINE FUEL SUCTION FEED SYSTEM (REF FAA AD 2013-13-11) REF TASK 28-022-04 | G727: REFER TO RC# 20097-002
A728: 20121-0001 | B728: - | C728: 27-450-00-01 | D728: VQ-BXJ-1 | E728: ROUTINE | F728: INSPECT (DETAILED) THE STABILIZER TRIM BALLSCREW, BALLNUT, AND BALLNUT RETURN TUBES. REF TASK 27-450-00-01 | G728: COMPLETED.
A729: 20121-0002 | B729: - | C729: 25-135-00-01 | D729: VQ-BXJ-1 | E729: ROUTINE | F729: VISUALLY CHECK THE FIRST AID KITS. REF TASK 25-135-00-01 | G729: COMPLETED.
A730: 20121-0003 | B730: - | C730: 25-160-00-01 | D730: VQ-BXJ-1 | E730: ROUTINE | F730: OPERATIONALLY CHECK EMERGENCY FLASHLIGHTS. (INCLUDING FLASHLIGHTS IN THE LOWER LOBE ATTENDANT REST, FLIGHT CREW REST AND OVERHEAD FLIGHT CREW/ATTENDANT REST IF INSTALLED). REF TASK 25-160-00-01 | G730: COMPLETED.
A731: 20121-0004 | B731: - | C731: 26-270-00-01 | D731: VQ-BXJ-1 | E731: ROUTINE | F731: INSPECT (DETAILED) LAVATORY WASTE COMPARTMENT FIRE EXTINGUISHER BOTTLES FOR CORRECT WEIGHT AND TEMPERATURE INDICATOR AND EXTINGUISHER FUSIBLE TIPS FOR CONDITION. (INCLUDING BOTTLES IN LAVATORIES IN OVERHEAD FLIGHT CREW/ATTENDANT REST AREAS IF INSTALLED.) REF TASK 26-270-00-01 | G731: COMPLETED.
A732: 20121-0005 | B732: - | C732: 53-868-00-01 | D732: VQ-BXJ-1 | E732: ROUTINE | F732: INTERNAL - ZONAL (GV): BULK CARGO COMPARTMENT PERFORM AN INTERNAL ZONAL INSPECTION (GV) OF THE BULK CARGO COMPARTMENT REF TASK 53-868-00-01 | G732: CANCELLED BY CAMO.
A733: 20121-0006 | B733: - | C733: 12-024-00-01 | D733: VQ-BXJ-1 | E733: ROUTINE | F733: LUBRICATE THE WING AILERON POWER CONTROL UNIT (PCU'S) ROD ENDS AND REACTION LINKS, AND AILERON HINGE FITTINGS. REF TASK 12-024-00-01 | G733: COMPLETED.
A734: 20121-0007 | B734: - | C734: 12-024-00-02 | D734: VQ-BXJ-1 | E734: ROUTINE | F734: LUBRICATE THE WING AILERON POWER CONTROL UNIT (PCU'S) ROD ENDS AND REACTION LINKS, AND AILERON HINGE FITTINGS. REF TASK 12-024-00-02 | G734: COMPLETED.
A735: 20121-0008 | B735: - | C735: 12-026-00-01 | D735: VQ-BXJ-1 | E735: ROUTINE | F735: LUBRICATE FLAPERON POWER CONTROL UNIT (PCU'S) ROD ENDS, HINGE FITTINGS AND PCU YOKE ASSEMBLIES (IF INSTALLED) NOTE: THE NEW FLAPERON PCU YOKE ASSEMBLIES WERE INTRODUCED AT LINE POSITION 357 AND ON OR INCORPORATED THROUGH SB 777-27-0049. EXAMINE THE FLAPERON PCU YOKE ASSEMBLIES FOR GREASE FITTINGS. IF PRESENT, LUBRICATE THE YOKE ASSEMBLIES (4 FITTINGS). REF TASK 12-026-00-01 | G735: COMPLETED.
A736: 20121-0009 | B736: - | C736: 12-026-00-02 | D736: VQ-BXJ-1 | E736: ROUTINE | F736: LUBRICATE FLAPERON POWER CONTROL UNIT (PCU'S) ROD ENDS, HINGE FITTINGS AND PCU YOKE ASSEMBLIES (IF INSTALLED) NOTE: THE NEW FLAPERON PCU YOKE ASSEMBLIES WERE INTRODUCED AT LINE POSITION 357 AND ON OR INCORPORATED THROUGH SB 777-27-0049. EXAMINE THE FLAPERON PCU YOKE ASSEMBLIES FOR GREASE FITTINGS. IF PRESENT, LUBRICATE THE YOKE ASSEMBLIES (4 FITTINGS). REF TASK 12-026-00-02 | G736: COMPLETED.
...

Sheet GAES EEF Registry
A1: EEF Number | B1: NRC Number | C1: AC Type | D1: ATA | E1: Project No. | F1: Subject | G1: Remarks | H1: Location | I1: EEF Status | J1: Link | K1: Link Path | L1: Man Hours | M1: Chargeable to Customer? | N1: Customer Name | O1: Inspection Source Task | P1: RC# | Q1: Open Date | R1: Assigned Engineering Engineer | S1: OPEN/Continuation Raised by Production Dates | T1: Answer provided by Engineering Dates | U1: OEM Communication Reference | V1: GAES EO | W1: Manual limits (OUT / WITHIN) | X1: Back-up Engineer | Y1: Project Status | Z1: EEF Priority | AA1: Latest Processing | AB1: Project Status2
A2: 2025-0627 | B2: 20315-0752 | C2: B747-400 | D2: 53 | E2: ER-BAJ-2 | F2: RH WING INBD FLAP O/B RIB AT GUIDE ROLLER FITTING CRACKED | G2: Fitting replacement | H2: WITH PRODUCTION | I2: CLOSED | J2: =IF(K2="","",HYPERLINK(K2, "Link")) -> Link | K2: K:\ENGINEERING\Engineering Enquiry Forms\2025 EEF PDF FORMAT (SCAN)\EEF 2025-0627 ER-BAJ-2 | L2: 5 | M2: YES | N2: AERO TRANSCARGO | P2: =IF((VLOOKUP(B2,'Work Card Inquiry'!A:E,5,FALSE))="NONROUTINE",VLOOKUP(B2,'Work Card Inquiry'!A:E,2,FALSE), B2) -> #N/A | Q2: 45910 | R2: AMARNATH
A3: 2025-0626 | B3: 20315-0751 | C3: B747-400 | D3: 57 | E3: ER-BAJ-2 | F3: LH WING INBD FLAP O/B RIB AT GUIDE ROLLER FITTING CRACKED | G3: Fitting replacement | H3: WITH PRODUCTION | I3: CLOSED | J3: =IF(K3="","",HYPERLINK(K3, "Link")) -> Link | K3: K:\ENGINEERING\Engineering Enquiry Forms\2025 EEF PDF FORMAT (SCAN)\EEF 2025-0626 ER-BAJ-2 | L3: 5 | M3: YES | N3: AERO TRANSCARGO | P3: =IF((VLOOKUP(B3,'Work Card Inquiry'!A:E,5,FALSE))="NONROUTINE",VLOOKUP(B3,'Work Card Inquiry'!A:E,2,FALSE), B3) -> #N/A | Q3: 45910 | R3: AMARNATH
A4: 2025-0625 | B4: 20790-0093 | C4: B777-200 | D4: 25 | E4: ER-BOY-1 | F4: MID AND AFT GALLEY SPIGOT LEVER INTERCHANGEABILTIY | G4: Clarification sent to OEM, Due to the P/N CS-340-12 (FAUCET) is not referenced in CMM 25-04-57. | H4: WITH PRODUCTION | I4: CLOSED | J4: =IF(K4="","",HYPERLINK(K4, "Link")) -> Link | K4: K:\ENGINEERING\Engineering Enquiry Forms\2025 EEF PDF FORMAT (SCAN)\EEF 2025-0625 ER-BOY-1 | L4: 4 | M4: YES | N4: AQULINE INTERNATIONAL | P4: =IF((VLOOKUP(B4,'Work Card Inquiry'!A:E,5,FALSE))="NONROUTINE",VLOOKUP(B4,'Work Card Inquiry'!A:E,2,FALSE), B4) -> #N/A | Q4: 45909 | R4: AMARNATH
A5: 2025-0624 | B5: 20790-0169 | C5: B777-200 | D5: 72 | E5: ER-BOY-1 | F5: FAN BLADE LUBRICATION - MATERIAL INTERCHANGEABILITY FOR OMAT 876A | G5: w Boeing to confirm correct material. ETS 13 Sep # Jeewana Request has been sent to Customer Waiting for response # Jeewana UNDER ENGINEERING EVALUATION | H5: WITH OEM | I5: OPEN | J5: =IF(K5="","",HYPERLINK(K5, "Link")) -> Link | K5: T:\3. Departmental Folders\10 Technical Services\ENGINEERING\Engineering Enquiry Forms\2025 EEF PDF FORMAT (SCAN)\EEF 2025-0624 ER-BOY-1 | L5: TBD | M5: YES | N5: AQULINE INTERNATIONAL | O5: TASK: 72-346-01 | P5: =IF((VLOOKUP(B5,'Work Card Inquiry'!A:E,5,FALSE))="NONROUTINE",VLOOKUP(B5,'Work Card Inquiry'!A:E,2,FALSE), B5) -> #N/A | Q5: 45908 | R5: JEEWANA
A6: 2025-0623 | B6: 20790-0087 | C6: B777-200 | D6: 57 | E6: ER-BOY-1 | F6: LH FLAPERON COVER LIP DOOR FITTING REPLCEMENT | G6: Blind Bolt removal & Replacement instructions provided # Jeewana | H6: WITH PRODUCTION | I6: CLOSED | J6: =IF(K6="","",HYPERLINK(K6, "Link")) -> Link | K6: T:\3. Departmental Folders\10 Technical Services\ENGINEERING\Engineering Enquiry Forms\2025 EEF PDF FORMAT (SCAN)\EEF 2025-0623 ER-BOY-1 | L6: 3 | M6: YES | N6: AQULINE INTERNATIONAL | O6: TASK: 57-520-01 | P6: =IF((VLOOKUP(B6,'Work Card Inquiry'!A:E,5,FALSE))="NONROUTINE",VLOOKUP(B6,'Work Card Inquiry'!A:E,2,FALSE), B6) -> #N/A | Q6: 45904 | R6: JEEWANA
A7: 2025-0622 | B7: 20790-0089CWR-002 | C7: B777-200 | D7: 25 | E7: ER-BOY-1 | F7: ALL LAVATORY FUACET'S ARE LEAKING - PRE/POST CONFIG LISTED IN CMM - P/N IDENTIFICATION | G7: #Subhash 3. CMM received, orrder Part IAW CMM 2.Requested CMM from customer 1. Under Evaluation | H7: WITH PRODUCTION | I7: CLOSED | J7: =IF(K7="","",HYPERLINK(K7, "Link")) -> Link | K7: T:\3. Departmental Folders\10 Technical Services\ENGINEERING\Engineering Enquiry Forms\2025 EEF PDF FORMAT (SCAN)\EEF 2025-0622 ER-BOY-1 | L7: 5 | M7: YES | N7: AQULINE INTERNATIONAL | O7: CWR-002 | P7: =IF((VLOOKUP(B7,'Work Card Inquiry'!A:E,5,FALSE))="NONROUTINE",VLOOKUP(B7,'Work Card Inquiry'!A:E,2,FALSE), B7) -> #N/A | Q7: 45903 | R7: SUBHASH
A8: 2025-0621 | B8: 20790-0094 | C8: B777-200 | D8: 25 | E8: ER-BOY-1 | F8: FWD GALLEY WATER LINE HOSE MISSING AND CONFIGURATION NOT MARCHING WITH CMM - P/N IDENTIFICATION - REPLACEMENT | G8: #Chandu (#SCA-2025-09-001452) wOEM, clamp P/N & Hose Assy P/N received from SAFRAN | H8: WITH PRODUCTION | I8: CLOSED | J8: =IF(K8="","",HYPERLINK(K8, "Link")) -> Link | K8: T:\3. Departmental Folders\10 Technical Services\ENGINEERING\Engineering Enquiry Forms\2025 EEF PDF FORMAT (SCAN)\EEF 2025-0621 ER-BOY-1 | L8: 6 | M8: YES | N8: AQULINE INTERNATIONAL | O8: CWR-002 | P8: =IF((VLOOKUP(B8,'Work Card Inquiry'!A:E,5,FALSE))="NONROUTINE",VLOOKUP(B8,'Work Card Inquiry'!A:E,2,FALSE), B8) -> #N/A | Q8: 45900 | R8: CHANDU
A9: 2025-0620 | B9: 21069-0002 | C9: B777-200 | D9: 53 | E9: ER-BOY-1 | F9: FUSELAGE EXTERNAL SKIN AND SHEAR CLIPS - AT STA 1916 & BETWEEN STGR 42R & 43R - DENT | G9: w Prod awaiting doubler material # Jeewana 4. Production request for deviation to the doubler materials & request sent to customer for approval 3. Doubler & Filler thickness provided to Production. 2. Additional Clarification requested by production. 1. Initial Instructions issued to perform repair as per SRM 53-00-01 R04 | H9: WITH PRODUCTION | I9: OPEN | J9: =IF(K9="","",HYPERLINK(K9, "Link")) -> Link | K9: T:\3. Departmental Folders\10 Technical Services\ENGINEERING\Engineering Enquiry Forms\2025 EEF PDF FORMAT (SCAN)\EEF 2025-0620 ER-BOY-1 | L9: 6 | M9: YES | N9: AQULINE INTERNATIONAL | O9: SR-BOY-53-221 | P9: =IF((VLOOKUP(B9,'Work Card Inquiry'!A:E,5,FALSE))="NONROUTINE",VLOOKUP(B9,'Work Card Inquiry'!A:E,2,FALSE), B9) -> #N/A | Q9: 45897 | R9: JEEWANA
A10: 2025-0619 | B10: 21000-0052 | C10: B747-400 | D10: 52 | E10: ER-BOS-1 | F10: APU DOOR SKIN REPAIR - FABRICATION REQUEST | G10: Answered | H10: WITH PRODUCTION | I10: CLOSED | J10: =IF(K10="","",HYPERLINK(K10, "Link")) -> Link | K10: T:\3. Departmental Folders\10 Technical Services\ENGINEERING\Engineering Enquiry Forms\2025 EEF PDF FORMAT (SCAN)\EEF 2025-0619 ER-BOS-1 | L10: TBD | M10: NO | N10: AQULINE INTERNATIONAL | O10: 53-924-01 | P10: =IF((VLOOKUP(B10,'Work Card Inquiry'!A:E,5,FALSE))="NONROUTINE",VLOOKUP(B10,'Work Card Inquiry'!A:E,2,FALSE), B10) -> #N/A | Q10: 45896 | R10: JEEWANA
A11: 2025-0618 | B11: 20790-0097 | C11: B777-200 | D11: 57 | E11: ER-BOY-1 | F11: LH WING TE LOWER ACCESS PANEL SUPPORT BEAM BTW IRSS 805 TO 850 AND CHORD ASSY AT 831.76 - CRACK - REPLACEMENT | G11: # Chandu ETS 27 Aug Replace as per DWG | H11: WITH PRODUCTION | I11: CLOSED | J11: =IF(K11="","",HYPERLINK(K11, "Link")) -> Link | K11: T:\3. Departmental Folders\10 Technical Services\ENGINEERING\Engineering Enquiry Forms\2025 EEF PDF FORMAT (SCAN)\EEF 2025-0618 ER-BOY-1 | L11: 3 | M11: YES | N11: AQULINE INTERNATIONAL | O11: 57-868-01-01 | P11: =IF((VLOOKUP(B11,'Work Card Inquiry'!A:E,5,FALSE))="NONROUTINE",VLOOKUP(B11,'Work Card Inquiry'!A:E,2,FALSE), B11) -> #N/A | Q11: 45895 | R11: CHANDU
A12: 2025-0617 | B12: 20790-0035 | C12: B777-200 | D12: 57 | E12: ER-BOY-1 | F12: CORROSSION ON LH WING LWR SURFACE SKIN BTWN WS1035 AND WS1055 | G12: w V1 for approval document 1.Under Evaluation 2. Damage report in progress, requested drawing for skin thickness. 3. Requested production for additional NDT fot UT (ETS 28-Aug). 4. Reported to customer 5. Awaiting approval for PO from customer 6. Quote approved, With V1 for repair 7. Repair completed, reported to V1 | H12: WITH DER | I12: OPEN | J12: =IF(K12="","",HYPERLINK(K12, "Link")) -> Link | K12: T:\3. Departmental Folders\10 Technical Services\ENGINEERING\Engineering Enquiry Forms\2025 EEF PDF FORMAT (SCAN)\EEF 2025-0617 ER-BOY-1 | L12: 4 | M12: YES | N12: AQULINE INTERNATIONAL | O12: 57-840-01-01 | P12: =IF((VLOOKUP(B12,'Work Card Inquiry'!A:E,5,FALSE))="NONROUTINE",VLOOKUP(B12,'Work Card Inquiry'!A:E,2,FALSE), B12) -> #N/A | Q12: 45894 | R12: SUBHASH
A13: 2025-0616 | B13: 20790-0033 | C13: B777-200 | D13: 57 | E13: ER-BOY-1 | F13: CORROSSION ON LH WING LWR SURFACE SKIN BTWN WS 916 AND STA WS942 | G13: w V1 for approval document 1. Damage report in progress, requested drawing for skin thickness. 2. Requested production for additional NDT fot UT 3. Reported to customer 4. Hangar for additional information. 5. Reported to customer. 6. Awaiting approval for PO from customer 7. Quote approved, With V1 for repair 8. Repair completed, reported to V1 | H13: WITH DER | I13: OPEN | J13: =IF(K13="","",HYPERLINK(K13, "Link")) -> Link | K13: T:\3. Departmental Folders\10 Technical Services\ENGINEERING\Engineering Enquiry Forms\2025 EEF PDF FORMAT (SCAN)\EEF 2025-0616 ER-BOY-1 | L13: 4 | M13: YES | N13: AQULINE INTERNATIONAL | O13: 57-840-01-01 | P13: =IF((VLOOKUP(B13,'Work Card Inquiry'!A:E,5,FALSE))="NONROUTINE",VLOOKUP(B13,'Work Card Inquiry'!A:E,2,FALSE), B13) -> #N/A | Q13: 45894 | R13: SUBHASH
A14: 2025-0615 | B14: 21017-0114 | C14: B747-400F | D14: 32 | E14: 9H-AKF-1 | F14: RH WING LANDING GEAR UP-LOCK QUADRANT -REPLACEMENT PROCEDURE CLARIFICATION | G14: Replace as per CMM 32-32-23 | H14: WITH PRODUCTION | I14: CLOSED | J14: =IF(K14="","",HYPERLINK(K14, "Link")) -> Link | K14: T:\3. Departmental Folders\10 Technical Services\ENGINEERING\Engineering Enquiry Forms\2025 EEF PDF FORMAT (SCAN)\EEF 2025-0615 9H-AKF-1 | L14: 3 | M14: NO | N14: AIR ATLANTA EUROPE | O14: 4N-20-004-00-02 | P14: =IF((VLOOKUP(B14,'Work Card Inquiry'!A:E,5,FALSE))="NONROUTINE",VLOOKUP(B14,'Work Card Inquiry'!A:E,2,FALSE), B14) -> #N/A | Q14: 45894 | R14: CHANDU
A15: 2025-0614 | B15: 20790-0061 | C15: B777-200 | D15: 53 | E15: ER-BOY-1 | F15: LOWER FUSELAGE SKIN STA 1546.5,S-49R - CORROSSION | G15: #Subash Approval document issued to production Repair completed, reported to V1. w Prod, Final repair instruction received to leave it as-is. Repair in progress. | H15: WITH PRODUCTION | I15: CLOSED | J15: =IF(K15="","",HYPERLINK(K15, "Link")) -> Link | K15: T:\3. Departmental Folders\10 Technical Services\ENGINEERING\Engineering Enquiry Forms\2025 EEF PDF FORMAT (SCAN)\EEF 2025-0614 ER-BOY-1 | L15: 6 | M15: YES | N15: AQULINE INTERNATIONAL | O15: 53-894-00-01 | P15: =IF((VLOOKUP(B15,'Work Card Inquiry'!A:E,5,FALSE))="NONROUTINE",VLOOKUP(B15,'Work Card Inquiry'!A:E,2,FALSE), B15) -> #N/A | Q15: 45894 | R15: SUBHASH
A16: 2025-0613 | B16: 21000-0013 | C16: B747-400 | D16: 38 | E16: ER-BOS-1 | F16: LWR FUSELAGE FWD DRAIN MAST - CORROSION - P/N CLARIFICATION | G16: Requested CMM from customer. Replace as per AIPC 38-31-01-01 | H16: WITH PRODUCTION | I16: CLOSED | J16: =IF(K16="","",HYPERLINK(K16, "Link")) -> Link | K16: T:\3. Departmental Folders\10 Technical Services\ENGINEERING\Engineering Enquiry Forms\2025 EEF PDF FORMAT (SCAN)\EEF 2025-0613 ER-BOS-1 | L16: 2 | M16: NO | N16: AQULINE INTERNATIONAL | O16: 53-804-01 | P16: =IF((VLOOKUP(B16,'Work Card Inquiry'!A:E,5,FALSE))="NONROUTINE",VLOOKUP(B16,'Work Card Inquiry'!A:E,2,FALSE), B16) -> #N/A | Q16: 45893 | R16: SUBHASH
A17: 2025-0612 | B17: 21054-0003 | C17: B747-400F | D17: 73 | E17: 9H-AKF-1 | F17: Engine #4 ECU INSTALLATION LIMITATIONS - SB CLARIFICATION | G17: Accepteable to install, as there are no restrictions in SB | H17: WITH PRODUCTION | I17: CLOSED | J17: =IF(K17="","",HYPERLINK(K17, "Link")) -> Link | K17: T:\3. Departmental Folders\10 Technical Services\ENGINEERING\Engineering Enquiry Forms\2025 EEF PDF FORMAT (SCAN)\EEF 2025-0612 9H-AKF-1 | L17: 4 | M17: NO | N17: AIR ATLANTA EUROPE | O17: R-72-131-02-01 | P17: =IF((VLOOKUP(B17,'Work Card Inquiry'!A:E,5,FALSE))="NONROUTINE",VLOOKUP(B17,'Work Card Inquiry'!A:E,2,FALSE), B17) -> #N/A | Q17: 45893 | R17: CHANDU
A18: 2025-0611 | B18: 20790-0090 | C18: B777-200 | D18: 53 | E18: ER-BOY-1 | F18: BELLY FAIRING SUPPORT BRACKETS CRACKED AT STA 1035 AND 1245 - CRACK - REPLACEMENT | G18: # Chandu ETS 27 Aug Replace as per DWG | H18: WITH PRODUCTION | I18: CLOSED | J18: =IF(K18="","",HYPERLINK(K18, "Link")) -> Link | K18: T:\3. Departmental Folders\10 Technical Services\ENGINEERING\Engineering Enquiry Forms\2025 EEF PDF FORMAT (SCAN)\EEF 2025-0611 ER-BOY-1 | L18: 3 | M18: YES | N18: AQULINE INTERNATIONAL | O18: 53-890-00-01 | P18: =IF((VLOOKUP(B18,'Work Card Inquiry'!A:E,5,FALSE))="NONROUTINE",VLOOKUP(B18,'Work Card Inquiry'!A:E,2,FALSE), B18) -> #N/A | Q18: 45891 | R18: CHANDU
A19: 2025-0610 | B19: 20790-0062 | C19: B777-200 | D19: 53 | E19: ER-BOY-1 | F19: SUPPORT BRACKET ON STRUCTURE ASSY-AFT FAIRING STA 1476 TO 1546.5 @ BL 0 - CRACKS | G19: Drawing requested from customer The damaged Bracket is identified as P/N: 149W5182 Part To Bre Replaced # Jeewana | H19: WITH PRODUCTION | I19: CLOSED | J19: =IF(K19="","",HYPERLINK(K19, "Link")) -> Link | K19: T:\3. Departmental Folders\10 Technical Services\ENGINEERING\Engineering Enquiry Forms\2025 EEF PDF FORMAT (SCAN)\EEF 2025-0610 ER-BOY | L19: 4 | M19: YES | N19: AQULINE INTERNATIONAL | O19: TASK: 53-894-00 | P19: =IF((VLOOKUP(B19,'Work Card Inquiry'!A:E,5,FALSE))="NONROUTINE",VLOOKUP(B19,'Work Card Inquiry'!A:E,2,FALSE), B19) -> #N/A | Q19: 45889 | R19: JEEWANA
A20: 2025-0609 | B20: 20790-0023 | C20: B777-200 | D20: 53 | E20: ER-BOY-1 | F20: UNDER WING FAIRING SPORT LOWER ACCESS FAIRING195ML FWD ATTACHMENT BRACKET - CORROSION | G20: Damage part is identified on Assy P/N 149W2171-1, specifically affecting Part P/N 149W2171-3 manufactured from BAC1518-1070 (7075-T6); as the assembly, part, and extrusion are not available, the customer has confirmed that the Frame Assembly P/N: 149W2171-1 will be supplied # Jeewana | H20: WITH PRODUCTION | I20: CLOSED | J20: =IF(K20="","",HYPERLINK(K20, "Link")) -> Link | K20: T:\3. Departmental Folders\10 Technical Services\ENGINEERING\Engineering Enquiry Forms\2025 EEF PDF FORMAT (SCAN)\EEF 2025-0609 ER-BOY | L20: 4 | M20: YES | N20: AQULINE INTERNATIONAL | O20: TASK: 53-800-00-03 | P20: =IF((VLOOKUP(B20,'Work Card Inquiry'!A:E,5,FALSE))="NONROUTINE",VLOOKUP(B20,'Work Card Inquiry'!A:E,2,FALSE), B20) -> #N/A | Q20: 45889 | R20: JEEWANA
A21: 2025-0608 | B21: 21017-0072 | C21: B747-400F | D21: 54 | E21: 9H-AKF-1 | F21: MULTIPLE DENTS ON ENG# 3 ACOUSTIC PANEL LOWER SKIN | G21: # Jeewana ETS 29 Aug w Prod, Final repair instructions received from V1. Repair completed. FAA 8110-3 Recived & EEF Closed | H21: WITH PRODUCTION | I21: CLOSED | J21: =IF(K21="","",HYPERLINK(K21, "Link")) -> Link | K21: T:\3. Departmental Folders\10 Technical Services\ENGINEERING\Engineering Enquiry Forms\2025 EEF PDF FORMAT (SCAN)\EEF 2025-0608 9H-AKF-1 | L21: 4 | M21: YES | N21: AIR ATLANTA EUROPE | O21: 4N-71-802-01-03 | P21: =IF((VLOOKUP(B21,'Work Card Inquiry'!A:E,5,FALSE))="NONROUTINE",VLOOKUP(B21,'Work Card Inquiry'!A:E,2,FALSE), B21) -> #N/A | Q21: 45888 | R21: JEEWANA
A22: 2025-0607 | B22: 21017 - 0106 | C22: B747-400F | D22: 53 | E22: 9H-AKF-1 | F22: MULTIPLE CRACKS ON FUSELAGE SKIN - LAP SPLICE UPPER FASTENER ROW BETWEEN STA 1440 AND STA 1480 AT S-23L | G22: w Prod, Final repair instructions received from V1. Repair completed & reported back to V1. Final approval & AMOC Received | H22: WITH PRODUCTION | I22: CLOSED | J22: =IF(K22="","",HYPERLINK(K22, "Link")) -> Link | K22: T:\3. Departmental Folders\10 Technical Services\ENGINEERING\Engineering Enquiry Forms\2025 EEF PDF FORMAT (SCAN)\EEF 2025-0607 9H-AKF-1 | L22: 30 | M22: YES | N22: AIR ATLANTA EUROPE | O22: FAA AD 2024-19-01 | P22: =IF((VLOOKUP(B22,'Work Card Inquiry'!A:E,5,FALSE))="NONROUTINE",VLOOKUP(B22,'Work Card Inquiry'!A:E,2,FALSE), B22) -> #N/A | Q22: 45887 | R22: AMARNATH
... A26: 2025-0603 | B26: 20956-0009 | C26: B747-400F | D26: 32 | E26: TF-AKG-9 | F26: LH Wing Landing Gear Door - FWD Seal Retainer - Crack | G26: (SR# V1-02919) #Jeewana 2. w V1 initial reapir proposal rejected. Raw material and part N/A. 1. w V1, Rejected Repair proposal Customer Is preferred to replace the door | H26: WITH PRODUCTION | I26: CLOSED | J26: =IF(K26="","",HYPERLINK(K26, "Link")) -> Link | K26: T:\3. Departmental Folders\10 Technical Services\ENGINEERING\Engineering Enquiry Forms\2025 EEF PDF FORMAT (SCAN)\EEF 2025-0603 TF-AKG-9 | L26: 3 | M26: YES | N26: AIR ATLANTA ICELANDIC | O26: CWR-009 | P26: =IF((VLOOKUP(B26,'Work Card Inquiry'!A:E,5,FALSE))="NONROUTINE",VLOOKUP(B26,'Work Card Inquiry'!A:E,2,FALSE), B26) -> 20956-0009 | Q26: 45873 | R26: JEEWANA
A27: 2025-0602 | B27: 20911-0124 | C27: B747-400F | D27: 52 | E27: TF-AKG-9 | F27: AFT CARGO DOOR CLOSING SWITH BRACKET - CORROSION - REPLACEMENT P/N IDENTIFICATION | G27: Replace the affected bracket P/N 65B04719-20. | H27: WITH PRODUCTION | I27: CLOSED | J27: =IF(K27="","",HYPERLINK(K27, "Link")) -> Link | K27: T:\3. Departmental Folders\10 Technical Services\ENGINEERING\Engineering Enquiry Forms\2025 EEF PDF FORMAT (SCAN)\EEF 2025-0602 TF-AKG-9 | L27: 5 | M27: YES | N27: AIR ATLANTA ICELANDIC | O27: MPD-52-410-00-02 | P27: =IF((VLOOKUP(B27,'Work Card Inquiry'!A:E,5,FALSE))="NONROUTINE",VLOOKUP(B27,'Work Card Inquiry'!A:E,2,FALSE), B27) -> 20909-0493 | Q27: 45866 | R27: SUBHASH | T27: 45867 | W27: OUT | Z27: NORMAL | AA27: ANSWERED
A28: 2025-0601 | B28: 20988-0056 | C28: B777-200 | D28: 53 | E28: 4L-MWB-1 | F28: FUSELAGE SKIN STA 164.75 - 188.5 ABOVE WINDOW 2 - PUNCTURE (FOD DAMAGE) - DOUBLER REPAIR | G28: BCS MA6-MA6-25-0018 # Jeewana ETS TBD 4. w Prod to close the access, top coat restoration, Final EEF issued. 3. Repair prfrmd, with no deviation from (-5B msg) FAA 8100-9 received. 2. w Boeing - Damage report and repair proposal submitted. 1. w Hangar - Preliminary instructions for damage removal and inspection. | H28: WITH PRODUCTION | I28: CLOSED | J28: =IF(K28="","",HYPERLINK(K28, "Link")) -> Link | K28: T:\3. Departmental Folders\10 Technical Services\ENGINEERING\Engineering Enquiry Forms\2025 EEF PDF FORMAT (SCAN)\EEF 2025-0601 4L-MWB-1 | L28: 15 | M28: YES | N28: MY WAY AIRLINES | O28: 53-898-00-02 | P28: =IF((VLOOKUP(B28,'Work Card Inquiry'!A:E,5,FALSE))="NONROUTINE",VLOOKUP(B28,'Work Card Inquiry'!A:E,2,FALSE), B28) -> 20985-0395 | Q28: 45861 | R28: JEEWANA | W28: OUT | X28: Dmitry | AA28: ANSWERED
A29: 2025-0600 | B29: 20985-0425 | C29: B777-200 | D29: 54 | E29: 4L-MWB-1 | F29: LH AND RH PYLON STRUCT AFT FAIRING GAP COVER STRIPS REPLACEMENT - EO Request | G29: 1. EO issued IAW SRM 54-51-70. #AMARNATH | H29: WITH PRODUCTION | I29: CLOSED | J29: =IF(K29="","",HYPERLINK(K29, "Link")) -> Link | K29: T:\3. Departmental Folders\10 Technical Services\ENGINEERING\Engineering Enquiry Forms\2025 EEF PDF FORMAT (SCAN)\EEF 2025-0600 4L-MWB | L29: 1 | M29: YES | N29: MY WAY AIRLINES | O29: SRM 54-51-70 | P29: =IF((VLOOKUP(B29,'Work Card Inquiry'!A:E,5,FALSE))="NONROUTINE",VLOOKUP(B29,'Work Card Inquiry'!A:E,2,FALSE), B29) -> 20985-0425 | Q29: 45859 | R29: AMARNATH | AA29: ANSWERED
A30: 2025-0599 | B30: 20994-0001 | C30: A320-232P2F | D30: 32 | E30: SU-SKD-1 | F30: LH MLG SIDE STAY - CORROSION - BRUSH PLATING PER PCS-2141 IS REQUIRED - ALTERNATE PLATING PROCEDURE REQUEST | G30: 1. Re-protection as per SRM is acceptable by Safran, if the solution meets the requirements of AMS2451/4. #JEEWANA | H30: WITH PRODUCTION | I30: CLOSED | J30: =IF(K30="","",HYPERLINK(K30, "Link")) -> Link | K30: T:\3. Departmental Folders\10 Technical Services\ENGINEERING\Engineering Enquiry Forms\2025 EEF PDF FORMAT (SCAN)\EEF 2025-0599 SU-SKD-1 | L30: 3 | M30: YES | N30: SKY VISION AIRLINES | O30: RDAS-SLS-2025-06-1833 | P30: =IF((VLOOKUP(B30,'Work Card Inquiry'!A:E,5,FALSE))="NONROUTINE",VLOOKUP(B30,'Work Card Inquiry'!A:E,2,FALSE), B30) -> - | Q30: 45856 | R30: JEEWANA | S30: A: 7/18/2025 | W30: TBD
A31: 2025-0598 | B31: 20956-0005 | C31: B747-400F | D31: 78 | E31: TF-AKG-9 | F31: ENG#1 LH TRANSLATING COWL UPPER BEAVERTAIL FAIRING - POTENTIAL CRACK | G31: 3. Repair as per CMM 2. NDT reports from Production #SUBHASH, 1. PAINT HAS BEEN REMOVED AND CONFIRMED THE SEPERATION OF THE UPPER BEAVERTAIL FAIRING AND SKIN. | H31: WITH PRODUCTION | I31: CLOSED | J31: =IF(K31="","",HYPERLINK(K31, "Link")) -> Link | K31: T:\3. Departmental Folders\10 Technical Services\ENGINEERING\Engineering Enquiry Forms\2025 EEF PDF FORMAT (SCAN)\EEF 2025-0598 TF-AKG-9 | L31: 6 | M31: YES | N31: AIR ATLANTA ICELANDIC | O31: CWR-005 | P31: =IF((VLOOKUP(B31,'Work Card Inquiry'!A:E,5,FALSE))="NONROUTINE",VLOOKUP(B31,'Work Card Inquiry'!A:E,2,FALSE), B31) -> 20956-0005 | Q31: 45855 | R31: SUBHASH | Y31: WIP | AA31: ANSWERED
A32: 2025-0597 | B32: 20905-0085 | C32: B747-400F | D32: 57 | E32: 9H-FLM-1 | F32: LH NAVIGATION LIGHT LENS - P/N INTERCHANGEABILITY CLARIFICATION | G32: 2. CORRECT REPLACEMENT PART IS LENS ASSEMBLY P/N: 284U7032-21. 1. IT IS NOT ACCEPTABLE TO INSTALL PMA LENS PIN: N284U7032-71 DUE TO SIGNIFICANT CONFIGURATION DEVIATION. #JEEWANA | H32: WITH PRODUCTION | I32: CLOSED | J32: =IF(K32="","",HYPERLINK(K32, "Link")) -> Link | K32: T:\3. Departmental Folders\10 Technical Services\ENGINEERING\Engineering Enquiry Forms\2025 EEF PDF FORMAT (SCAN)\EEF 2025-0597 9H-FLM-1 | L32: 3 | M32: YES | N32: AIR ATLANTA EUROPE LTD | O32: MPD-57-806-01-01 | P32: =IF((VLOOKUP(B32,'Work Card Inquiry'!A:E,5,FALSE))="NONROUTINE",VLOOKUP(B32,'Work Card Inquiry'!A:E,2,FALSE), B32) -> 20903-0336 | R32: JEEWANA
A33: 2025-0596 | B33: 20930-0015 20930-0074 | C33: A320-214 | D33: 53 | E33: A6-AOJ | F33: FUSELAGE SKIN - EXISTING (NOT REGISTERED) REWORKS MULTIPLE FINDINGS AFTER PAINT STRIPPING | G33: w Airbus for RDAF 81620479_003_2025#A Recived TD_81620479_005_2025 received & all reworked areas found to be acceptable as per TD. Damage noted while prfrmng SRM 51-75-11 Acid paint stripper before re-painting EEF Closed Dossie# 81620479 # Jeewana | H33: WITH PRODUCTION | I33: CLOSED | J33: =IF(K33="","",HYPERLINK(K33, "Link")) -> Link | K33: K:\ENGINEERING\Engineering Enquiry Forms\2025 EEF PDF FORMAT (SCAN)\EEF 2025-0596 A6-AOJ-1 | L33: 7 | M33: YES | N33: AIR ARABIA PJSC | O33: 3854599 (PAINT) SRM 51-75-11 | P33: =IF((VLOOKUP(B33,'Work Card Inquiry'!A:E,5,FALSE))="NONROUTINE",VLOOKUP(B33,'Work Card Inquiry'!A:E,2,FALSE), B33) -> #N/A | Q33: 45841 | R33: JEEWANA | S33: A: 7/3/2025 D: 7/10/2025 | T33: B: 7/4/2025 D: 7/11/2025 E:11-Jul-2025 | W33: OUT | AA33: ANSWERED
A34: 2025-0595 | B34: 20905-0176 | C34: B747-400F | D34: 53 | E34: 9H-FLM-1 | F34: FUSELAGE STRINGER SPLICE - STA 1740, S-35L - CRACK - P/N IDENTIFICATION | G34: (BCS# AID-AE8-25-0009-01C) # Chandu 1. w Production, to replace the damaged part with a new STRINGER CHANNEL - SPLICE P/N is 65B06895-13 as per BCS. | H34: WITH PRODUCTION | I34: CLOSED | J34: =IF(K34="","",HYPERLINK(K34, "Link")) -> Link | K34: T:\3. Departmental Folders\10 Technical Services\ENGINEERING\Engineering Enquiry Forms\2025 EEF PDF FORMAT (SCAN)\EEF 2025-0595 9H-FLM-1 | L34: 5 | M34: YES | N34: AIR ATLANTA EUROPE LTD | O34: B47-AD2002-23-15 SB 747-53A2487 | P34: =IF((VLOOKUP(B34,'Work Card Inquiry'!A:E,5,FALSE))="NONROUTINE",VLOOKUP(B34,'Work Card Inquiry'!A:E,2,FALSE), B34) -> 20904-0002 | Q34: 45841 | R34: CHANDU | U34: AID-AE8-25-0009-01C | W34: OUT
A35: 2025-0594 | B35: 20905-0016 | C35: B747-400F | D35: 78 | E35: 9H-FLM-1 | F35: ENG#2 RH THRUST REVERSER - LOWER ANGLE GEAR BOX MOUNT BRACKET - CRACKED | H35: WITH PRODUCTION | I35: CLOSED | J35: =IF(K35="","",HYPERLINK(K35, "Link")) -> Link | K35: T:\3. Departmental Folders\10 Technical Services\ENGINEERING\Engineering Enquiry Forms\2025 EEF PDF FORMAT (SCAN)\EEF 2025-0594 9H-FLM-1/ | L35: 2 | M35: NO | N35: AIR ATLANTA EUROPE LTD | O35: MPD-78-131-13-02 | P35: =IF((VLOOKUP(B35,'Work Card Inquiry'!A:E,5,FALSE))="NONROUTINE",VLOOKUP(B35,'Work Card Inquiry'!A:E,2,FALSE), B35) -> 20903-0377 | Q35: 45839 | R35: SUBHASH | T35: 45839 | W35: WITHIN | X35: CHANDU | AA35: ANSWERED
A36: 2025-0593 | B36: 20948-0002 | C36: B747-400F | D36: 52 | E36: 9H-MSK | F36: RH WING INBD STRUT DOOR PUNCTURE REPAIR PARTS FABRICATION FORM REQUEST | G36: Answered | H36: WITH PRODUCTION | I36: CLOSED | J36: =IF(K36="","",HYPERLINK(K36, "Link")) -> Link | K36: T:\3. Departmental Folders\10 Technical Services\ENGINEERING\Engineering Enquiry Forms\2025 EEF PDF FORMAT (SCAN)\EEF 2025-0593 9H-MSK-11/ | L36: 2 | M36: YES | N36: QUICK LINK AVIATION SERVICES (FZC) | O36: CWR-002 ITEM#6 | P36: =IF((VLOOKUP(B36,'Work Card Inquiry'!A:E,5,FALSE))="NONROUTINE",VLOOKUP(B36,'Work Card Inquiry'!A:E,2,FALSE), B36) -> 20948-0002 | Q36: 45833 | R36: JEEWANA | S36: B: 6/25/2025 | T36: A: 6/25/2025 | U36: N/A | W36: WITHIN | AA36: ANSWERED
A37: 2025-0592 | B37: 20949-0028 | C37: A321 | D37: 57 | E37: UK32120-4 | F37: VENT SURGE TANK VORTEX GENERATOR INSTALLED | G37: Answered | H37: WITH PRODUCTION | I37: CLOSED | J37: =IF(K37="","",HYPERLINK(K37, "Link")) -> Link | K37: T:\3. Departmental Folders\10 Technical Services\ENGINEERING\Engineering Enquiry Forms\2025 EEF PDF FORMAT (SCAN)\EEF 2025-0592 UK32120-4/ | L37: 3 | M37: YES | N37: SAM AIR LLC | O37: 281200-01-1 | P37: =IF((VLOOKUP(B37,'Work Card Inquiry'!A:E,5,FALSE))="NONROUTINE",VLOOKUP(B37,'Work Card Inquiry'!A:E,2,FALSE), B37) -> 20949-0028 | Q37: 45832 | R37: AMARNATH | S37: B: 6/30/2025 | T37: 45833 | U37: 81613747 | W37: WITHIN | AA37: ANSWERED
A38: 2025-0591 | B38: 20952-0014 | C38: A321 | D38: 54 | E38: UK32120-4 | F38: ENG#1 INLET COWL INNER BAREL AT 6-O CLOCK - ACOUSTIC MESH DAMAGE | G38: Answered | H38: WITH PRODUCTION | I38: CLOSED | J38: =IF(K38="","",HYPERLINK(K38, "Link")) -> Link | K38: T:\3. Departmental Folders\10 Technical Services\ENGINEERING\Engineering Enquiry Forms\2025 EEF PDF FORMAT (SCAN)\EEF 2025-0591 UK32120-4/ | L38: 5 | M38: YES | N38: SAM AIR LLC | O38: A321-Transit-01 | P38: =IF((VLOOKUP(B38,'Work Card Inquiry'!A:E,5,FALSE))="NONROUTINE",VLOOKUP(B38,'Work Card Inquiry'!A:E,2,FALSE), B38) -> 20949-0083 | Q38: 45830 | R38: SUBHASH | T38: B: 25-Jun-2025 C: 25-Jun-2025 D: 29-Jun-2025 | U38: ROHR/S240/2025_A COLLINS CV25-08525 | W38: OUT | X38: JEEWANA | AA38: ANSWERED
A39: 2025-0590 | B39: 20818-0001 | C39: B747-400F | D39: 52 | E39: CN-RGA-3 | F39: SB 747-32-2536_RO- PART FABRICATION REQUEST | G39: Answered | H39: WITH PRODUCTION | I39: CLOSED | J39: =IF(K39="","",HYPERLINK(K39, "Link")) -> Link | K39: T:\3. Departmental Folders\10 Technical Services\ENGINEERING\Engineering Enquiry Forms\2025 EEF PDF FORMAT (SCAN)\EEF 2025-0590 CN-RGA-3/ | L39: 2 | M39: NO | N39: ROYAL AIR MAROC | O39: SB 747-32-2536 R0 | P39: =IF((VLOOKUP(B39,'Work Card Inquiry'!A:E,5,FALSE))="NONROUTINE",VLOOKUP(B39,'Work Card Inquiry'!A:E,2,FALSE), B39) -> 20818-0001 | Q39: 45828 | R39: SUBHASH | T39: 45831 | W39: WITHIN | X39: AMARNATH | AA39: ANSWERED
A40: 2025-0589 | B40: 20889-0009 to 20889-0067 | C40: A320-214 | D40: 53 | E40: A6-AOI | F40: FUSELAGE SKIN - EXISTING (NOT REGISTERED) REWORKS MULTIPLE FINDINGS AFTER PAINT STRIPPING | G40: Answered Damage noted while prfrmng SRM 51-75-11 Acid paint stripper before re-painting | H40: WITH PRODUCTION | I40: CLOSED | J40: =IF(K40="","",HYPERLINK(K40, "Link")) -> Link | K40: T:\3. Departmental Folders\10 Technical Services\ENGINEERING\Engineering Enquiry Forms\2025 EEF PDF FORMAT (SCAN)\EEF 2025-0589 A6-AOI-1/ | L40: 5 | M40: YES | N40: AIR ARABIA PJSC | O40: 3854598 (PAINT) SRM 51-75-11 | P40: =IF((VLOOKUP(B40,'Work Card Inquiry'!A:E,5,FALSE))="NONROUTINE",VLOOKUP(B40,'Work Card Inquiry'!A:E,2,FALSE), B40) -> #N/A | Q40: 16-6-2025 | R40: JEEWANA | S40: A: 6/16/2025 D: 6/22/2025 | T40: B: 6/17/2025 C: 6/22/2025 E: 6/26/2025 | U40: Airbus Dossier 81611250 | W40: OUT | X40: CHANDU | AA40: ANSWERED
A41: 2025-0588 | B41: 20845-0003 | C41: B747-400F | D41: 28 | E41: CN-RGA-3 | F41: MAIN FUEL TANK # 1 FQIS WIRE - DAMAGE - SLEEVE REPAIR PER SWPM | G41: # Chandu 1. w Production, to replace the wire bundle will be the feseable option instead of the Sleeve repair per SWPM 20-14-12, as the sleve repair requires FAA oversight approval which will take 30-60days. | H41: WITH PRODUCTION | I41: CLOSED | J41: =IF(K41="","",HYPERLINK(K41, "Link")) -> Link | K41: T:\3. Departmental Folders\10 Technical Services\ENGINEERING\Engineering Enquiry Forms\2025 EEF PDF FORMAT (SCAN)\EEF 2025-0588 CN-RGA-3/ | L41: 9 | M41: YES | N41: ROYAL AIR MAROC | O41: CWR-003 | P41: =IF((VLOOKUP(B41,'Work Card Inquiry'!A:E,5,FALSE))="NONROUTINE",VLOOKUP(B41,'Work Card Inquiry'!A:E,2,FALSE), B41) -> 20845-0003 | Q41: 45824 | R41: CHANDU | S41: A: 16-Jun-2025 | T41: B: 17-Jun-2025 | U41: RAM-MRC-25-0017 | W41: OUT | AA41: ANSWERED
A42: 2025-0587 | B42: 20885-0010 | C42: B747-400F | D42: 53 | E42: CN-RGA-3 | F42: FUSELAGE SKIN AT STA 741, STRG 26 - MULTIPLE DENTS ADJACENT TO REPAIR DOUBLER | G42: Answered. Unique dents not registered | H42: WITH PRODUCTION | I42: CLOSED | J42: =IF(K42="","",HYPERLINK(K42, "Link")) -> Link | K42: T:\3. Departmental Folders\10 Technical Services\ENGINEERING\Engineering Enquiry Forms\2025 EEF PDF FORMAT (SCAN)\EEF 2025-0587 CN-RGA-3/ | L42: 5 | M42: YES | N42: ROYAL AIR MAROC | O42: AMES/MP/10-014 | P42: =IF((VLOOKUP(B42,'Work Card Inquiry'!A:E,5,FALSE))="NONROUTINE",VLOOKUP(B42,'Work Card Inquiry'!A:E,2,FALSE), B42) -> 20885-0010 | Q42: 45819 | R42: SUBHASH | S42: 45833 | T42: B: 19-Jun-2025 | U42: RAM-MRC-25-0014 | W42: OUT | AA42: ANSWERED
A43: 2025-0586 | B43: 20823-0165 | C43: B747-400F | D43: 54 | E43: CN-RGA-3 | F43: ENG#2 OUTBD FAIRING REPAIR - FABRICATION REQUEST | G43: Answered | H43: WITH PRODUCTION | I43: CLOSED | J43: =IF(K43="","",HYPERLINK(K43, "Link")) -> Link | K43: T:\3. Departmental Folders\10 Technical Services\ENGINEERING\Engineering Enquiry Forms\2025 EEF PDF FORMAT (SCAN)\EEF 2025-0586 CN-RGA-3/ | L43: 2 | M43: NO | N43: ROYAL AIR MAROC | O43: 54-812-00-02 | P43: =IF((VLOOKUP(B43,'Work Card Inquiry'!A:E,5,FALSE))="NONROUTINE",VLOOKUP(B43,'Work Card Inquiry'!A:E,2,FALSE), B43) -> 20808-0217 | Q43: 45818 | R43: SUBHASH | T43: 45818 | W43: WITHIN | AA43: ANSWERED
...
